# rust

## [panic!]

> 当代码出问题了,rust会执行`panic!`宏.当执行这个宏时,程序会打印出一个错误信息,展开并清理栈数据,然后接着退出

* **对应`panic`时的栈展开或终止**

1. 当出现 panic 时,程序默认会开始**展开(unwinding)**,这意味着 Rust 会**回溯**栈并清理它遇到的每一个函数的数据(清理调用栈),不过这个回溯并清理的过程有很多工作.
2. 另一种选择是直接**终止(abort)**,这会不清理数据就退出程序.那么程序所使用的内存需要由操作系统来清理.

* 如果你需要项目的最终二进制文件越小越好,在`Cargo.toml`添加以下操作,可以由展开切换为终止.
* 例如,如果你想要在release模式中`panic`时直接终止:

```toml
[profile.release]
panic = 'abort'
```

> Rust错误的分类

1. 可恢复:例如文件未找到.可以再次尝试
2. 不可恢复:bug,例如索引超出范围

* 由于rust没有一场的机制,如果是可恢复错误`Result<T,E>`.不可恢复的错误就是`panic!`宏
* 通过调用`panic!`的函数的回溯信息来定位引起问题的代码,可以设置环境变量`RUST_BACKTRACE=1`来回溯信息
  * `set RUST_BACKTRACE=1 && cargo run`
  * 或者也可以设置`RUST_BACKTRACE=full`获得所有问题的信息
* 为了获得带有调试信息的回溯,必须启用调试符号(不带`--release`)

### Result

```rs
enum Result<T,E>{
  Ok(T),
  Err(E)
}
```

* `T`:操作成功,返回的数据类型
* `E`:操作失败,返回的数据类型

>使用match处理Result

* 和Option枚举一样,Result及其变体也是有prelude带入作用域

```rs
use std::fs::File;
fn main() {
  let f = File::open("hello.txt");
  match f {
    Ok(file) => file,
    Err(error) => {
      panic!("There was a problem opening the file: {:?}", error);
    }
  };
}
```

>`unwrap`:match表达式的快捷方法

* 如果Result结果是Ok,返回里面Ok的值
* 如果Result的结果是Err,调用`panic!`宏

```rs
let f = File::Open("hello.txt").unwrap();
```

>`expect`:和unwarp类似,但可指定错误信息

* 如果使用`unwarp`,由于不能指定错误,很难定位位置

```rs
let f = File::Open("hello.txt").expect("无法打开文件");
```

#### 传播错误

> 在函数出处处理错误,将错误返回给调用者

* `?`:rust中使用`?`来简化错误的传播

```rs
use std::fs::File;
use std::io;
use std::io::Read;
fn read_username_from_file() -> Result<String, io::Error> {

  //这个?就相当于以下代码.成功就输出Ok(file),失败就返回Err(e)
  let mut f =File::open("hello.txt")?;
  //let f = File::open("hello.txt");
  //let mut f = match f {
  //  Ok(file) => file,
  //  Err(e) => return Err(e),
  //};
  let mut s = String::new();
  f.read_to_string(&mut s)?;
  //match f.read_to_string(&mut s) {
  //  Ok(_) => Ok(s),
  //  Err(e) => Err(e),
  //}
  
  //如果成功,整个函数返回s(读入的字符)
  Ok(s)
}
```

* 如果Result是Ok:Ok就是表达式的结果,然后继续执行程序
* 如果Result是Err:Err就是整个函数的返回值,就像使用了return

>`?`与`from`函数

* Trait std::convert::From上的from函数:
  * 用于错误之间的转换
* 被`?`所应用的错误,会隐式的被from寒素处理
* 当`?`调用from函数时
  * 他所接收的错误类型会被转化为当前函数返回类型所定义的错误类型
* <span style="color:red">用于:针对不同错误原因,返回同一种错误类型</span>
  * 只要每个错误类型实现了转换为所返回错误类型的from函数

>同时可以使用链式调用

```rs
let mut s = String::new();
File::open("hello.txt")?.read_to_string(&mut s)?;
Ok(s)
```

* <span style="color:red">?运算符只能用于返回结果是`Result`或者`Option`的函数,或者实现了`Try`类型</span>

### [use panic!]

>再顶一个一个可能失败的函数时,优先返回result,否则就`panic!`

* 使用`panic!`的情况
  * 演示某些概念:`unwrap`
  * 原型代码:`unwrap`,`expect`
  * 测试:`unwrap`,`expect`

>如果可以确定Result就是Ok的:`unwrap`

```rs
use std::net::IpAddr;
fn main(){
  let home:IpAddr = "127.0.0.1".parse().unwrap();
}
```

>当代码最终可能处于损坏状态时,最好使用`panic`

* 损坏状态(Bad state):某些假设,保证,约定不可变性被打破
  * 例如非法的值,矛盾或者空缺的值被传入代码
  * 以及下列的任意一条
    * 这种损坏转台并不是预期能够偶尔发生的事
    * 在此之后,代码如果处于这种损坏状态无法运行

1. 调用你的代码,传入无意义的参数值,`panic!`
2. 调用外部不可控的代码,返回非法状态,无法修复`panic!`
3. 如果失败事可预期的`Result`
4. 当你的代码对值进行操作,首先应该验证这些值:`panic!`

>自定义类型

* 创建新的类型,把验证逻辑放在构造实例的函数里

```rs
use std::io;

fn main() {
  loop {
    let mut guess = String::new();
    io::stdin().read_line(&mut guess).expect("无法读取值");
    let guess: i32 = match guess.trim().parse() {
      Ok(num) => num,
      Err(_) => continue,
    };
    Guess::new(guess);
  }
}
pub struct Guess {
  value: i32,
}

impl Guess {
  pub fn new(value: i32) -> Guess {
    if value < 1 || value > 100 {
      panic!("输入错误,请输入1-100之间的数字");
    }
    Guess { value }
  }
  pub fn value(&self) -> i32 {
    self.value
  }
}
```
